<sdf version='1.7'>
  <world name='default'>
    <model name='ground_plane'>
      <static>1</static>
      <link name='link'>
        <collision name='collision'>
          <geometry>
            <plane>
              <normal>0 0 1</normal>
              <size>100 100</size>
            </plane>
          </geometry>
          <surface>
            <friction>
              <ode>
                <mu>100</mu>
                <mu2>50</mu2>
              </ode>
              <torsional>
                <ode/>
              </torsional>
            </friction>
            <contact>
              <ode/>
            </contact>
            <bounce/>
          </surface>
          <max_contacts>10</max_contacts>
        </collision>
        <visual name='visual'>
          <cast_shadows>0</cast_shadows>
          <geometry>
            <plane>
              <normal>0 0 1</normal>
              <size>100 100</size>
            </plane>
          </geometry>
          <material>
            <script>
              <uri>file://media/materials/scripts/gazebo.material</uri>
              <name>Gazebo/Grey</name>
            </script>
          </material>
        </visual>
        <self_collide>0</self_collide>
        <enable_wind>0</enable_wind>
        <kinematic>0</kinematic>
      </link>
    </model>
    <light name='sun' type='directional'>
      <cast_shadows>1</cast_shadows>
      <pose>0 0 10 0 -0 0</pose>
      <diffuse>0.8 0.8 0.8 1</diffuse>
      <specular>0.2 0.2 0.2 1</specular>
      <attenuation>
        <range>1000</range>
        <constant>0.9</constant>
        <linear>0.01</linear>
        <quadratic>0.001</quadratic>
      </attenuation>
      <direction>-0.5 0.1 -0.9</direction>
      <spot>
        <inner_angle>0</inner_angle>
        <outer_angle>0</outer_angle>
        <falloff>0</falloff>
      </spot>
    </light>
    <scene>
      <shadows>0</shadows>
      <ambient>0.4 0.4 0.4 1</ambient>
      <background>0.7 0.7 0.7 1</background>
    </scene>
    <gui fullscreen='0'>
      <camera name='user_camera'>
        <pose>2.34839 3.43205 3.56181 0 0.665801 -1.6864</pose>
        <view_controller>orbit</view_controller>
        <projection_type>perspective</projection_type>
      </camera>
    </gui>
    <physics type='ode'>
      <real_time_update_rate>1000</real_time_update_rate>
      <max_step_size>0.001</max_step_size>
      <real_time_factor>1</real_time_factor>
      <ode>
        <solver>
          <type>quick</type>
          <iters>150</iters>
          <precon_iters>0</precon_iters>
          <sor>1.4</sor>
          <use_dynamic_moi_rescaling>1</use_dynamic_moi_rescaling>
        </solver>
        <constraints>
          <cfm>1e-05</cfm>
          <erp>0.2</erp>
          <contact_max_correcting_vel>2000</contact_max_correcting_vel>
          <contact_surface_layer>0.01</contact_surface_layer>
        </constraints>
      </ode>
    </physics>
    <gravity>0 0 -9.8</gravity>
    <magnetic_field>6e-06 2.3e-05 -4.2e-05</magnetic_field>
    <atmosphere type='adiabatic'/>
    <audio>
      <device>default</device>
    </audio>
    <wind/>
    <spherical_coordinates>
      <surface_model>EARTH_WGS84</surface_model>
      <latitude_deg>0</latitude_deg>
      <longitude_deg>0</longitude_deg>
      <elevation>0</elevation>
      <heading_deg>0</heading_deg>
    </spherical_coordinates>
    <model name='waffle_pi'>
      <pose>0 0 0.01 0 -0 0</pose>
      <link name='base_footprint'>
        <self_collide>0</self_collide>
        <inertial>
          <pose>0 0 0 0 -0 0</pose>
          <inertia>
            <ixx>1</ixx>
            <ixy>0</ixy>
            <ixz>0</ixz>
            <iyy>1</iyy>
            <iyz>0</iyz>
            <izz>1</izz>
          </inertia>
          <mass>1</mass>
        </inertial>
        <enable_wind>0</enable_wind>
        <kinematic>0</kinematic>
      </link>
      <link name='base_link'>
        <inertial>
          <pose>-0.064 0 0.048 0 -0 0</pose>
          <inertia>
            <ixx>0.0421114</ixx>
            <ixy>0</ixy>
            <ixz>0</ixz>
            <iyy>0.0421114</iyy>
            <iyz>0</iyz>
            <izz>0.0752549</izz>
          </inertia>
          <mass>1.37291</mass>
        </inertial>
        <collision name='base_collision'>
          <pose>-0.064 0 0.048 0 -0 0</pose>
          <geometry>
            <box>
              <size>0.265 0.265 0.089</size>
            </box>
          </geometry>
          <max_contacts>10</max_contacts>
          <surface>
            <contact>
              <ode/>
            </contact>
            <bounce/>
            <friction>
              <torsional>
                <ode/>
              </torsional>
              <ode/>
            </friction>
          </surface>
        </collision>
        <visual name='base_visual'>
          <pose>-0.064 0 0 0 -0 0</pose>
          <geometry>
            <mesh>
              <uri>model://turtlebot3_common/meshes/waffle_pi_base.dae</uri>
              <scale>0.001 0.001 0.001</scale>
            </mesh>
          </geometry>
        </visual>
        <self_collide>0</self_collide>
        <enable_wind>0</enable_wind>
        <kinematic>0</kinematic>
      </link>
      <link name='imu_link'>
        <sensor name='tb3_imu' type='imu'>
          <always_on>1</always_on>
          <update_rate>200</update_rate>
          <imu>
            <angular_velocity>
              <x>
                <noise type='gaussian'>
                  <mean>0</mean>
                  <stddev>0.0002</stddev>
                </noise>
              </x>
              <y>
                <noise type='gaussian'>
                  <mean>0</mean>
                  <stddev>0.0002</stddev>
                </noise>
              </y>
              <z>
                <noise type='gaussian'>
                  <mean>0</mean>
                  <stddev>0.0002</stddev>
                </noise>
              </z>
            </angular_velocity>
            <linear_acceleration>
              <x>
                <noise type='gaussian'>
                  <mean>0</mean>
                  <stddev>0.017</stddev>
                </noise>
              </x>
              <y>
                <noise type='gaussian'>
                  <mean>0</mean>
                  <stddev>0.017</stddev>
                </noise>
              </y>
              <z>
                <noise type='gaussian'>
                  <mean>0</mean>
                  <stddev>0.017</stddev>
                </noise>
              </z>
            </linear_acceleration>
            <angular_velocity/>
            <linear_acceleration/>
          </imu>
          <plugin name='turtlebot3_imu' filename='libgazebo_ros_imu_sensor.so'>
            <ros>
              <remapping>~/out:=imu</remapping>
            </ros>
          </plugin>
        </sensor>
        <self_collide>0</self_collide>
        <inertial>
          <pose>0 0 0 0 -0 0</pose>
          <inertia>
            <ixx>1</ixx>
            <ixy>0</ixy>
            <ixz>0</ixz>
            <iyy>1</iyy>
            <iyz>0</iyz>
            <izz>1</izz>
          </inertia>
          <mass>1</mass>
        </inertial>
        <enable_wind>0</enable_wind>
        <kinematic>0</kinematic>
      </link>
      <link name='base_scan'>
        <inertial>
          <pose>-0.052 0 0.111 0 -0 0</pose>
          <inertia>
            <ixx>0.001</ixx>
            <ixy>0</ixy>
            <ixz>0</ixz>
            <iyy>0.001</iyy>
            <iyz>0</iyz>
            <izz>0.001</izz>
          </inertia>
          <mass>0.114</mass>
        </inertial>
        <collision name='lidar_sensor_collision'>
          <pose>-0.052 0 0.111 0 -0 0</pose>
          <geometry>
            <cylinder>
              <radius>0.0508</radius>
              <length>0.055</length>
            </cylinder>
          </geometry>
          <max_contacts>10</max_contacts>
          <surface>
            <contact>
              <ode/>
            </contact>
            <bounce/>
            <friction>
              <torsional>
                <ode/>
              </torsional>
              <ode/>
            </friction>
          </surface>
        </collision>
        <visual name='lidar_sensor_visual'>
          <pose>-0.064 0 0.121 0 -0 0</pose>
          <geometry>
            <mesh>
              <uri>model://turtlebot3_common/meshes/lds.dae</uri>
              <scale>0.001 0.001 0.001</scale>
            </mesh>
          </geometry>
        </visual>
        <sensor name='hls_lfcd_lds' type='ray'>
          <always_on>1</always_on>
          <visualize>1</visualize>
          <pose>-0.064 0 0.121 0 -0 0</pose>
          <update_rate>5</update_rate>
          <ray>
            <scan>
              <horizontal>
                <samples>360</samples>
                <resolution>1</resolution>
                <min_angle>0</min_angle>
                <max_angle>6.28</max_angle>
              </horizontal>
              <vertical>
                <samples>1</samples>
                <min_angle>0</min_angle>
                <max_angle>0</max_angle>
              </vertical>
            </scan>
            <range>
              <min>0.12</min>
              <max>3.5</max>
              <resolution>0.015</resolution>
            </range>
            <noise>
              <type>gaussian</type>
              <mean>0</mean>
              <stddev>0.01</stddev>
            </noise>
          </ray>
          <plugin name='turtlebot3_laserscan' filename='libgazebo_ros_ray_sensor.so'>
            <ros>
              <remapping>~/out:=scan</remapping>
            </ros>
            <output_type>sensor_msgs/LaserScan</output_type>
            <frame_name>base_scan</frame_name>
          </plugin>
        </sensor>
        <self_collide>0</self_collide>
        <enable_wind>0</enable_wind>
        <kinematic>0</kinematic>
      </link>
      <link name='wheel_left_link'>
        <inertial>
          <pose>0 0.144 0.023 -1.57 0 0</pose>
          <inertia>
            <ixx>0.00181582</ixx>
            <ixy>-9.3392e-12</ixy>
            <ixz>1.04909e-11</ixz>
            <iyy>0.00329221</iyy>
            <iyz>5.75694e-11</iyz>
            <izz>0.00181582</izz>
          </inertia>
          <mass>0.0284989</mass>
        </inertial>
        <collision name='wheel_left_collision'>
          <pose>0 0.144 0.023 -1.57 0 0</pose>
          <geometry>
            <cylinder>
              <radius>0.033</radius>
              <length>0.018</length>
            </cylinder>
          </geometry>
          <surface>
            <friction>
              <ode>
                <mu>100000</mu>
                <mu2>100000</mu2>
                <fdir1>0 0 0</fdir1>
                <slip1>0</slip1>
                <slip2>0</slip2>
              </ode>
              <torsional>
                <ode/>
              </torsional>
            </friction>
            <contact>
              <ode>
                <soft_cfm>0</soft_cfm>
                <soft_erp>0.2</soft_erp>
                <kp>100000</kp>
                <kd>1</kd>
                <max_vel>0.01</max_vel>
                <min_depth>0.001</min_depth>
              </ode>
            </contact>
            <bounce/>
          </surface>
          <max_contacts>10</max_contacts>
        </collision>
        <visual name='wheel_left_visual'>
          <pose>0 0.144 0.023 0 -0 0</pose>
          <geometry>
            <mesh>
              <uri>model://turtlebot3_common/meshes/tire.dae</uri>
              <scale>0.001 0.001 0.001</scale>
            </mesh>
          </geometry>
        </visual>
        <self_collide>0</self_collide>
        <enable_wind>0</enable_wind>
        <kinematic>0</kinematic>
      </link>
      <link name='wheel_right_link'>
        <inertial>
          <pose>0 -0.144 0.023 -1.57 0 0</pose>
          <inertia>
            <ixx>0.00181582</ixx>
            <ixy>-9.3392e-12</ixy>
            <ixz>1.04909e-11</ixz>
            <iyy>0.00329221</iyy>
            <iyz>5.75694e-11</iyz>
            <izz>0.00181582</izz>
          </inertia>
          <mass>0.0284989</mass>
        </inertial>
        <collision name='wheel_right_collision'>
          <pose>0 -0.144 0.023 -1.57 0 0</pose>
          <geometry>
            <cylinder>
              <radius>0.033</radius>
              <length>0.018</length>
            </cylinder>
          </geometry>
          <surface>
            <friction>
              <ode>
                <mu>100000</mu>
                <mu2>100000</mu2>
                <fdir1>0 0 0</fdir1>
                <slip1>0</slip1>
                <slip2>0</slip2>
              </ode>
              <torsional>
                <ode/>
              </torsional>
            </friction>
            <contact>
              <ode>
                <soft_cfm>0</soft_cfm>
                <soft_erp>0.2</soft_erp>
                <kp>100000</kp>
                <kd>1</kd>
                <max_vel>0.01</max_vel>
                <min_depth>0.001</min_depth>
              </ode>
            </contact>
            <bounce/>
          </surface>
          <max_contacts>10</max_contacts>
        </collision>
        <visual name='wheel_right_visual'>
          <pose>0 -0.144 0.023 0 -0 0</pose>
          <geometry>
            <mesh>
              <uri>model://turtlebot3_common/meshes/tire.dae</uri>
              <scale>0.001 0.001 0.001</scale>
            </mesh>
          </geometry>
        </visual>
        <self_collide>0</self_collide>
        <enable_wind>0</enable_wind>
        <kinematic>0</kinematic>
      </link>
      <link name='caster_back_right_link'>
        <pose>-0.177 -0.064 -0.004 -1.57 0 0</pose>
        <inertial>
          <mass>0.001</mass>
          <inertia>
            <ixx>1e-05</ixx>
            <ixy>0</ixy>
            <ixz>0</ixz>
            <iyy>1e-05</iyy>
            <iyz>0</iyz>
            <izz>1e-05</izz>
          </inertia>
          <pose>0 0 0 0 -0 0</pose>
        </inertial>
        <collision name='collision'>
          <geometry>
            <sphere>
              <radius>0.005</radius>
            </sphere>
          </geometry>
          <surface>
            <contact>
              <ode>
                <soft_cfm>0</soft_cfm>
                <soft_erp>0.2</soft_erp>
                <kp>100000</kp>
                <kd>1</kd>
                <max_vel>0.01</max_vel>
                <min_depth>0.001</min_depth>
              </ode>
            </contact>
            <bounce/>
            <friction>
              <torsional>
                <ode/>
              </torsional>
              <ode/>
            </friction>
          </surface>
          <max_contacts>10</max_contacts>
        </collision>
        <self_collide>0</self_collide>
        <enable_wind>0</enable_wind>
        <kinematic>0</kinematic>
      </link>
      <link name='caster_back_left_link'>
        <pose>-0.177 0.064 -0.004 -1.57 0 0</pose>
        <inertial>
          <mass>0.001</mass>
          <inertia>
            <ixx>1e-05</ixx>
            <ixy>0</ixy>
            <ixz>0</ixz>
            <iyy>1e-05</iyy>
            <iyz>0</iyz>
            <izz>1e-05</izz>
          </inertia>
          <pose>0 0 0 0 -0 0</pose>
        </inertial>
        <collision name='collision'>
          <geometry>
            <sphere>
              <radius>0.005</radius>
            </sphere>
          </geometry>
          <surface>
            <contact>
              <ode>
                <soft_cfm>0</soft_cfm>
                <soft_erp>0.2</soft_erp>
                <kp>100000</kp>
                <kd>1</kd>
                <max_vel>0.01</max_vel>
                <min_depth>0.001</min_depth>
              </ode>
            </contact>
            <bounce/>
            <friction>
              <torsional>
                <ode/>
              </torsional>
              <ode/>
            </friction>
          </surface>
          <max_contacts>10</max_contacts>
        </collision>
        <self_collide>0</self_collide>
        <enable_wind>0</enable_wind>
        <kinematic>0</kinematic>
      </link>
      <link name='camera_link'>
        <self_collide>0</self_collide>
        <inertial>
          <pose>0 0 0 0 -0 0</pose>
          <inertia>
            <ixx>1</ixx>
            <ixy>0</ixy>
            <ixz>0</ixz>
            <iyy>1</iyy>
            <iyz>0</iyz>
            <izz>1</izz>
          </inertia>
          <mass>1</mass>
        </inertial>
        <enable_wind>0</enable_wind>
        <kinematic>0</kinematic>
      </link>
      <link name='camera_rgb_optical_frame'>
        <inertial>
          <pose>0.076 0 0.1 0 -0 0</pose>
          <inertia>
            <ixx>0.001</ixx>
            <ixy>0</ixy>
            <ixz>0</ixz>
            <iyy>0.001</iyy>
            <iyz>0</iyz>
            <izz>0.001</izz>
          </inertia>
          <mass>0.035</mass>
        </inertial>
        <pose>0.076 0 0.1 0 -0 0</pose>
        <sensor name='camera' type='depth'>
          <camera>
            <horizontal_fov>1.047</horizontal_fov>
            <image>
              <width>320</width>
              <height>240</height>
            </image>
            <clip>
              <near>0.1</near>
              <far>100</far>
            </clip>
          </camera>
          <plugin name='camera_controller' filename='libgazebo_ros_camera.so'>
            <ros>
              <namespace>demo_cam</namespace>
              <remapping>mycamera/image_raw:=mycamera/image_demo</remapping>
              <remapping>mycamera/depth/image_raw:=mycamera/depth_demo</remapping>
              <remapping>mycamera/camera_info:=mycamera/raw_cam_info_demo</remapping>
              <remapping>mycamera/depth/camera_info:=mycamera/depth_cam_info_demo</remapping>
              <remapping>mycamera/points:=mycamera/points_demo</remapping>
            </ros>
            <camera_name>mycamera</camera_name>
            <min_depth>0.1</min_depth>
            <max_depth>500</max_depth>
          </plugin>
          <always_on>1</always_on>
          <update_rate>30</update_rate>
          <visualize>1</visualize>
        </sensor>
        <self_collide>0</self_collide>
        <enable_wind>0</enable_wind>
        <kinematic>0</kinematic>
      </link>
      <joint name='base_joint' type='fixed'>
        <parent>base_footprint</parent>
        <child>base_link</child>
        <pose>0 0 0.01 0 -0 0</pose>
      </joint>
      <joint name='wheel_left_joint' type='revolute'>
        <parent>base_link</parent>
        <child>wheel_left_link</child>
        <pose>0 0.144 0.023 -1.57 0 0</pose>
        <axis>
          <xyz>0 0 1</xyz>
          <limit>
            <lower>-1e+16</lower>
            <upper>1e+16</upper>
          </limit>
          <dynamics>
            <spring_reference>0</spring_reference>
            <spring_stiffness>0</spring_stiffness>
          </dynamics>
        </axis>
      </joint>
      <joint name='wheel_right_joint' type='revolute'>
        <parent>base_link</parent>
        <child>wheel_right_link</child>
        <pose>0 -0.144 0.023 -1.57 0 0</pose>
        <axis>
          <xyz>0 0 1</xyz>
          <limit>
            <lower>-1e+16</lower>
            <upper>1e+16</upper>
          </limit>
          <dynamics>
            <spring_reference>0</spring_reference>
            <spring_stiffness>0</spring_stiffness>
          </dynamics>
        </axis>
      </joint>
      <joint name='caster_back_right_joint' type='ball'>
        <parent>base_link</parent>
        <child>caster_back_right_link</child>
      </joint>
      <joint name='caster_back_left_joint' type='ball'>
        <parent>base_link</parent>
        <child>caster_back_left_link</child>
      </joint>
      <joint name='imu_joint' type='fixed'>
        <parent>base_link</parent>
        <child>imu_link</child>
        <pose>-0.032 0 0.068 0 -0 0</pose>
        <axis>
          <xyz>0 0 1</xyz>
          <limit>
            <lower>-1e+16</lower>
            <upper>1e+16</upper>
          </limit>
        </axis>
      </joint>
      <joint name='lidar_joint' type='fixed'>
        <parent>base_link</parent>
        <child>base_scan</child>
        <pose>-0.064 0 0.121 0 -0 0</pose>
        <axis>
          <xyz>0 0 1</xyz>
          <limit>
            <lower>-1e+16</lower>
            <upper>1e+16</upper>
          </limit>
        </axis>
      </joint>
      <joint name='camera_joint' type='fixed'>
        <parent>base_link</parent>
        <child>camera_link</child>
        <pose>0.073 -0.011 0.084 0 -0 0</pose>
        <axis>
          <xyz>0 0 1</xyz>
          <limit>
            <lower>-1e+16</lower>
            <upper>1e+16</upper>
          </limit>
        </axis>
      </joint>
      <joint name='camera_rgb_joint' type='fixed'>
        <parent>camera_link</parent>
        <child>camera_rgb_optical_frame</child>
        <pose>0.003 0.011 0.009 0 -0 0</pose>
        <axis>
          <xyz>0 0 1</xyz>
          <limit>
            <lower>-1e+16</lower>
            <upper>1e+16</upper>
          </limit>
        </axis>
      </joint>
      <plugin name='turtlebot3_diff_drive' filename='libgazebo_ros_diff_drive.so'>
        <ros/>
        <update_rate>30</update_rate>
        <left_joint>wheel_left_joint</left_joint>
        <right_joint>wheel_right_joint</right_joint>
        <wheel_separation>0.287</wheel_separation>
        <wheel_diameter>0.066</wheel_diameter>
        <max_wheel_torque>20</max_wheel_torque>
        <max_wheel_acceleration>1.0</max_wheel_acceleration>
        <command_topic>cmd_vel</command_topic>
        <publish_odom>1</publish_odom>
        <publish_odom_tf>1</publish_odom_tf>
        <publish_wheel_tf>0</publish_wheel_tf>
        <odometry_topic>odom</odometry_topic>
        <odometry_frame>odom</odometry_frame>
        <robot_base_frame>base_footprint</robot_base_frame>
      </plugin>
      <plugin name='turtlebot3_joint_state' filename='libgazebo_ros_joint_state_publisher.so'>
        <ros>
          <remapping>~/out:=joint_states</remapping>
        </ros>
        <update_rate>30</update_rate>
        <joint_name>wheel_left_joint</joint_name>
        <joint_name>wheel_right_joint</joint_name>
      </plugin>
    </model>
    <model name='cricket_ball'>
      <link name='link'>
        <pose>0 0 0.0375 0 -0 0</pose>
        <inertial>
          <mass>0.1467</mass>
          <inertia>
            <ixx>8.25187e-05</ixx>
            <ixy>0</ixy>
            <ixz>0</ixz>
            <iyy>8.25187e-05</iyy>
            <iyz>0</iyz>
            <izz>8.25187e-05</izz>
          </inertia>
          <pose>0 0 0 0 -0 0</pose>
        </inertial>
        <collision name='collision'>
          <geometry>
            <sphere>
              <radius>0.0375</radius>
            </sphere>
          </geometry>
          <surface>
            <contact>
              <poissons_ratio>0.347</poissons_ratio>
              <elastic_modulus>8.8e+09</elastic_modulus>
              <ode>
                <kp>100000</kp>
                <kd>100</kd>
                <max_vel>100</max_vel>
                <min_depth>0.001</min_depth>
              </ode>
            </contact>
            <friction>
              <torsional>
                <coefficient>1</coefficient>
                <use_patch_radius>0</use_patch_radius>
                <surface_radius>0.01</surface_radius>
                <ode/>
              </torsional>
              <ode/>
            </friction>
            <bounce/>
          </surface>
          <max_contacts>10</max_contacts>
        </collision>
        <visual name='visual'>
          <geometry>
            <sphere>
              <radius>0.0375</radius>
            </sphere>
          </geometry>
          <material>
            <script>
              <uri>file://media/materials/scripts/gazebo.material</uri>
              <name>Gazebo/Red</name>
            </script>
          </material>
        </visual>
        <velocity_decay>
          <linear>0</linear>
          <angular>0.005</angular>
        </velocity_decay>
        <self_collide>0</self_collide>
        <enable_wind>0</enable_wind>
        <kinematic>0</kinematic>
      </link>
      <pose>1.96304 0.076584 0 0 -0 0</pose>
    </model>
    <state world_name='default'>
      <sim_time>401 286000000</sim_time>
      <real_time>402 880915357</real_time>
      <wall_time>1731822056 429240447</wall_time>
      <iterations>401286</iterations>
      <model name='cricket_ball'>
        <pose>1.96304 0.076584 -0.001014 0 -0 0</pose>
        <scale>1 1 1</scale>
        <link name='link'>
          <pose>1.96304 0.076584 0.036486 0 -0 0</pose>
          <velocity>0 0 0 0 -0 0</velocity>
          <acceleration>0 0 0 0 -0 0</acceleration>
          <wrench>0 0 0 0 -0 0</wrench>
        </link>
      </model>
      <model name='ground_plane'>
        <pose>0 0 0 0 -0 0</pose>
        <scale>1 1 1</scale>
        <link name='link'>
          <pose>0 0 0 0 -0 0</pose>
          <velocity>0 0 0 0 -0 0</velocity>
          <acceleration>0 0 0 0 -0 0</acceleration>
          <wrench>0 0 0 0 -0 0</wrench>
        </link>
      </model>
      <model name='waffle_pi'>
        <pose>4.8e-05 2e-06 0.007912 1.3e-05 0.006199 0.000507</pose>
        <scale>1 1 1</scale>
        <link name='base_footprint'>
          <pose>4.8e-05 2e-06 0.007912 1.3e-05 0.006199 0.000507</pose>
          <velocity>2.7e-05 -4.3e-05 -0.087434 -0.000158 0.002182 -1.6e-05</velocity>
          <acceleration>-0.002699 4.5e-05 -0.781883 0.00086 -0.261946 1.4e-05</acceleration>
          <wrench>-0.002699 4.5e-05 -0.781883 0 -0 0</wrench>
        </link>
        <link name='base_link'>
          <pose>4.8e-05 2e-06 0.007916 1.3e-05 0.006199 0.000507</pose>
          <velocity>2.7e-05 -4.3e-05 -0.088277 -0.000158 0.002208 -1.6e-05</velocity>
          <acceleration>-0.015376 3e-06 -0.797737 0.000855 -0.261969 1.1e-05</acceleration>
          <wrench>-0.02111 4e-06 -1.09522 0 -0 0</wrench>
        </link>
        <link name='base_scan'>
          <pose>4.8e-05 2e-06 0.007916 1.3e-05 0.006199 0.000507</pose>
          <velocity>2.7e-05 -4.4e-05 -0.08818 -0.000159 0.002204 -1.6e-05</velocity>
          <acceleration>-0.031861 -5e-05 -0.794583 0.000856 -0.261957 1.5e-05</acceleration>
          <wrench>-0.003632 -6e-06 -0.090582 0 -0 0</wrench>
        </link>
        <link name='camera_link'>
          <pose>4.8e-05 2e-06 0.007912 1.3e-05 0.006199 0.000507</pose>
          <velocity>3.1e-05 -4.4e-05 -0.087399 -0.000159 0.002122 -1.6e-05</velocity>
          <acceleration>-0.002704 4.6e-05 -0.781917 0.000861 -0.261881 1.5e-05</acceleration>
          <wrench>-0.002704 4.6e-05 -0.781917 0 -0 0</wrench>
        </link>
        <link name='camera_rgb_optical_frame'>
          <pose>0.076667 4e-05 0.107438 1.3e-05 0.006199 0.000507</pose>
          <velocity>0.000241 -3e-05 -0.087532 -0.000159 0.002117 -1.5e-05</velocity>
          <acceleration>-0.054832 -0.000122 -0.741815 0.000862 -0.261872 1.4e-05</acceleration>
          <wrench>-0.001919 -4e-06 -0.025964 0 -0 0</wrench>
        </link>
        <link name='caster_back_left_link'>
          <pose>-0.177005 0.063912 0.005015 1.29835 0.084674 0.922641</pose>
          <velocity>2.1e-05 -4.1e-05 -0.087884 0.006469 0.003699 -0</velocity>
          <acceleration>-0.001827 -0.000152 -0.830177 -0 -0 -0</acceleration>
          <wrench>-2e-06 -0 -0.00083 0 -0 0</wrench>
        </link>
        <link name='caster_back_right_link'>
          <pose>-0.17694 -0.064088 0.005013 0.675414 0.149251 0.413944</pose>
          <velocity>1.9e-05 -4.1e-05 -0.087861 0.005217 0.001605 0</velocity>
          <acceleration>-0.001869 -0.000186 -0.830854 -0 -0 -0</acceleration>
          <wrench>-2e-06 -0 -0.000831 0 -0 0</wrench>
        </link>
        <link name='imu_link'>
          <pose>4.8e-05 2e-06 0.007912 1.3e-05 0.006199 0.000507</pose>
          <velocity>3.1e-05 -4.4e-05 -0.087429 -0.00016 0.002127 -1.7e-05</velocity>
          <acceleration>-0.002705 4.7e-05 -0.781886 0.000861 -0.261879 1.6e-05</acceleration>
          <wrench>-0.002705 4.7e-05 -0.781886 0 -0 0</wrench>
        </link>
        <link name='wheel_left_link'>
          <pose>0.000107 2e-06 0.007927 1.3e-05 0.003627 0.000505</pose>
          <velocity>2e-05 1e-06 -0.090187 -0.000134 0.002205 -1.5e-05</velocity>
          <acceleration>-0.008645 -2.7e-05 -0.779099 0.000827 -0.261971 9e-06</acceleration>
          <wrench>-0.000246 -1e-06 -0.022203 0 -0 0</wrench>
        </link>
        <link name='wheel_right_link'>
          <pose>6e-06 2e-06 0.007927 1.3e-05 0.008025 0.000509</pose>
          <velocity>2.5e-05 1e-06 -0.090187 -0.000134 0.002211 -1.6e-05</velocity>
          <acceleration>-0.008646 -2.7e-05 -0.779198 0.000825 -0.261982 1.2e-05</acceleration>
          <wrench>-0.000246 -1e-06 -0.022206 0 -0 0</wrench>
        </link>
      </model>
      <light name='sun'>
        <pose>0 0 10 0 -0 0</pose>
      </light>
    </state>
  </world>
</sdf>
